Workbook

Sheet Guia
A1: Sistema de Controle de Estoque — Central, Fracionamento e Setores Consumidores
A2: Igor Morgado · Gerado em 09/07/2026
A4: Este arquivo controla o fluxo: Compra → Central de Distribuição → (Buffet Fran Casaria / Sushi / Restaurante Arboreto / Cozinha de Produção de Fracionados) → Produção de Fracionados → Estoque Fracionado → Sushi / Buffet Fran Casaria / Restaurante Arboreto.
A6: Aba | B6: Objetivo | C6: Uso Principal | D6: Cor das Células
A7: 1. Cadastro de Produtos Brutos | B7: Cadastro-mestre de todo insumo bruto comprado. | C7: Preencher 1x por produto novo. | D7: Azul = digitação
A8: 2. Cadastro de Produtos Fracionados | B8: Cadastro-mestre dos itens gerados pelo fracionamento. | C8: Preencher 1x por item fracionado novo. | D8: Azul = digitação
A9: 3. Cadastro de Locais | B9: Lista dos locais físicos/setores da operação. | C9: Preencher 1x, editar se abrir/fechar setor. | D9: Azul = digitação
A10: 4. Entrada na Central de Distribuição | B10: Registra toda compra/recebimento na Central. | C10: 1 linha por nota fiscal/item recebido. | D10: Azul = digitação, Verde = referência
A11: 5. Saída da Central de Distribuição | B11: Registra envio da Central para os 4 destinos. | C11: 1 linha por saída/transferência. | D11: Azul = digitação, Verde = referência
A12: 6. Produção de Fracionados | B12: Registra consumo de bruto na Cozinha de Fracionamento. | C12: 1 linha por insumo bruto usado no lote. | D12: Azul = digitação, Verde = referência
A13: 7. Entrada de Estoque Fracionado | B13: Registra o produto fracionado gerado pelo lote. | C13: 1 linha por lote de produção finalizado. | D13: Azul = digitação, Verde = referência
A14: 8. Saída de Estoque Fracionado | B14: Registra envio de fracionados para os setores. | C14: 1 linha por saída para Buffet/Sushi/Restaurante. | D14: Azul = digitação, Verde = referência
A15: 9. Movimentações Gerais | B15: Histórico único consolidado de todas as movimentações. | C15: Somente leitura — atualiza sozinho. | D15: Preto = fórmula (não editar)
A16: 10. Estoque Atual por Produto | B16: Saldo consolidado por produto (bruto e fracionado). | C16: Consulta — não editar. | D16: Preto = fórmula (não editar)
A17: 11. Estoque Atual por Local | B17: Saldo por produto x local físico. | C17: Consulta — não editar. | D17: Preto = fórmula (não editar)
... A19: 13. Dashboard Gerencial | B19: Indicadores e gráfico gerencial consolidado. | C19: Consulta gerencial. | D19: Preto = fórmula (não editar)
A21: Regras gerais:
A22: • Só digite em células AZUIS. Células PRETAS têm fórmula — nunca sobrescreva.
A23: • Sempre lance uma nova movimentação em uma NOVA linha, no final da tabela (nunca apague linhas antigas).
A24: • Os menus suspensos (setas ao lado da célula) evitam erro de digitação — sempre use-os.
A25: • O sistema bloqueia saídas maiores que o saldo disponível (mensagem de erro ao digitar).
A26: • As abas 9 a 13 são calculadas automaticamente a partir das abas 1 a 8 — não exigem digitação.

Sheet Cadastro Produtos Brutos
A1: Código do Produto | B1: Nome do Produto | C1: Categoria | D1: Unidade de Medida | E1: Estoque Mínimo | F1: Estoque Máximo | G1: Validade Padrão (dias) | H1: Fornecedor Padrão | I1: Preço Médio de Compra (R$) | J1: Ativo | K1: Observações
A2: BR-001 | B2: Salmão Fresco | C2: Peixes e Frutos do Mar | D2: KG | E2: 5 | F2: 50 | G2: 3 | H2: Fornecedor Mar Azul | I2: 42 | J2: Sim | K2: Manter refrigerado 0-4°C
A3: BR-002 | B3: Arroz Japonês | C3: Grãos e Cereais | D3: KG | E3: 10 | F3: 100 | G3: 180 | H3: Fornecedor Grão Bom | I3: 8.5 | J3: Sim | K3: Armazenar em local seco
A4: BR-003 | B4: Alface Americana | C4: Hortifruti | D4: UN | E4: 5 | F4: 40 | G4: 5 | H4: Fornecedor Horta Feliz | I4: 3.5 | J4: Sim
A5: BR-004 | B5: Filé de Frango | C5: Carnes | D5: KG | E5: 8 | F5: 60 | G5: 4 | H5: Fornecedor Avícola Sul | I5: 22 | J5: Sim | K5: Manter refrigerado 0-4°C
A6: BR-005 | B6: Tomate | C6: Hortifruti | D6: KG | E6: 5 | F6: 40 | G6: 6 | H6: Fornecedor Horta Feliz | I6: 6 | J6: Sim
A7: BR-006 | B7: Queijo Muçarela | C7: Laticínios | D7: KG | E7: 5 | F7: 30 | G7: 20 | H7: Fornecedor Laticínios Serra | I7: 32 | J7: Sim | K7: Manter refrigerado 0-4°C

Sheet Cadastro Produtos Fracionados
A1: Código Fracionado | B1: Nome do Produto Fracionado | C1: Categoria | D1: Unidade de Medida | E1: Código do Produto Bruto de Origem | F1: Nome do Produto Bruto de Origem | G1: Rendimento Padrão (%) | H1: Estoque Mínimo | I1: Estoque Máximo | J1: Validade Padrão Após Fracionamento (dias) | K1: Ativo | L1: Observações
A2: FR-001 | B2: Salmão Fatiado para Sushi | C2: Peixes e Frutos do Mar | D2: KG | E2: BR-001 | F2: =IFERROR(VLOOKUP(E2,'Cadastro Produtos Brutos'!$A:$B,2,0),"") -> Salmão Fresco | G2: 0.85 | H2: 2 | I2: 20 | J2: 2 | K2: Sim | L2: Porções de 20g
A3: FR-002 | B3: Arroz Temperado para Sushi | C3: Grãos e Cereais | D3: KG | E3: BR-002 | F3: =IFERROR(VLOOKUP(E3,'Cadastro Produtos Brutos'!$A:$B,2,0),"") -> Arroz Japonês | G3: 1.1 | H3: 3 | I3: 25 | J3: 2 | K3: Sim | L3: Temperado com vinagre/açúcar/sal
A4: FR-003 | B4: Alface Higienizada e Cortada | C4: Hortifruti | D4: KG | E4: BR-003 | F4: =IFERROR(VLOOKUP(E4,'Cadastro Produtos Brutos'!$A:$B,2,0),"") -> Alface Americana | G4: 0.8 | H4: 2 | I4: 15 | J4: 3 | K4: Sim | L4: Sanitizada em solução clorada
A5: FR-004 | B5: Frango Grelhado em Cubos | C5: Carnes | D5: KG | E5: BR-004 | F5: =IFERROR(VLOOKUP(E5,'Cadastro Produtos Brutos'!$A:$B,2,0),"") -> Filé de Frango | G5: 0.75 | H5: 2 | I5: 15 | J5: 3 | K5: Sim
A6: FR-005 | B6: Tomate Picado | C6: Hortifruti | D6: KG | E6: BR-005 | F6: =IFERROR(VLOOKUP(E6,'Cadastro Produtos Brutos'!$A:$B,2,0),"") -> Tomate | G6: 0.92 | H6: 2 | I6: 15 | J6: 2 | K6: Sim

Sheet Cadastro de Locais
A1: Código do Local | B1: Nome do Local | C1: Tipo de Local | D1: Responsável | E1: Ativo | F1: Observações
A2: CD-01 | B2: Central de Distribuição | C2: Central | D2: Igor Morgado | E2: Sim | F2: Recebe todas as compras
A3: LOC-01 | B3: Buffet Fran Casaria | C3: Consumidor | E3: Sim
A4: LOC-02 | B4: Sushi | C4: Consumidor | E4: Sim
A5: LOC-03 | B5: Restaurante Arboreto | C5: Consumidor | E5: Sim
A6: LOC-04 | B6: Cozinha de Produção de Fracionados | C6: Fracionamento | E6: Sim | F6: Recebe bruto e produz fracionado

Sheet Entrada na Central
A1: Data | B1: Nº NF/Documento | C1: Código do Produto | D1: Nome do Produto | E1: Unidade | F1: Fornecedor | G1: Quantidade | H1: Preço Unitário (R$) | I1: Valor Total (R$) | J1: Nº do Lote | K1: Data de Validade | L1: Responsável pelo Recebimento | M1: Observações
A2: 46204 | B2: NF-1001 | C2: BR-001 | D2: =IFERROR(VLOOKUP(C2,'Cadastro Produtos Brutos'!$A:$B,2,0),"") -> Salmão Fresco | E2: =IFERROR(VLOOKUP(C2,'Cadastro Produtos Brutos'!$A:$D,4,0),"") -> KG | F2: Fornecedor Mar Azul | G2: 40 | H2: 42 | I2: =IF(G2="","",G2*H2) -> 1680 | J2: L001 | K2: 46215 | L2: Igor Morgado
A3: 46204 | B3: NF-1002 | C3: BR-002 | D3: =IFERROR(VLOOKUP(C3,'Cadastro Produtos Brutos'!$A:$B,2,0),"") -> Arroz Japonês | E3: =IFERROR(VLOOKUP(C3,'Cadastro Produtos Brutos'!$A:$D,4,0),"") -> KG | F3: Fornecedor Grão Bom | G3: 30 | H3: 8.5 | I3: =IF(G3="","",G3*H3) -> 255 | J3: L002 | K3: 46388 | L3: Igor Morgado
A4: 46205 | B4: NF-1003 | C4: BR-004 | D4: =IFERROR(VLOOKUP(C4,'Cadastro Produtos Brutos'!$A:$B,2,0),"") -> Filé de Frango | E4: =IFERROR(VLOOKUP(C4,'Cadastro Produtos Brutos'!$A:$D,4,0),"") -> KG | F4: Fornecedor Avícola Sul | G4: 25 | H4: 22 | I4: =IF(G4="","",G4*H4) -> 550 | J4: L003 | K4: 46212 | L4: Igor Morgado
A5: 46205 | B5: NF-1004 | C5: BR-005 | D5: =IFERROR(VLOOKUP(C5,'Cadastro Produtos Brutos'!$A:$B,2,0),"") -> Tomate | E5: =IFERROR(VLOOKUP(C5,'Cadastro Produtos Brutos'!$A:$D,4,0),"") -> KG | F5: Fornecedor Horta Feliz | G5: 20 | H5: 6 | I5: =IF(G5="","",G5*H5) -> 120 | J5: L004 | K5: 46213 | L5: Igor Morgado
A6: 46206 | B6: NF-1005 | C6: BR-003 | D6: =IFERROR(VLOOKUP(C6,'Cadastro Produtos Brutos'!$A:$B,2,0),"") -> Alface Americana | E6: =IFERROR(VLOOKUP(C6,'Cadastro Produtos Brutos'!$A:$D,4,0),"") -> UN | F6: Fornecedor Horta Feliz | G6: 15 | H6: 3.5 | I6: =IF(G6="","",G6*H6) -> 52.5 | J6: L005 | K6: 46212 | L6: Igor Morgado

Sheet Saída da Central
A1: Data | B1: Nº Documento | C1: Código do Produto | D1: Nome do Produto | E1: Unidade | F1: Local de Destino | G1: Quantidade | H1: Saldo na Central Antes desta Saída | I1: Responsável | J1: Observações
A2: 46207 | B2: SC-001 | C2: BR-001 | D2: =IFERROR(VLOOKUP(C2,'Cadastro Produtos Brutos'!$A:$B,2,0),"") -> Salmão Fresco | E2: =IFERROR(VLOOKUP(C2,'Cadastro Produtos Brutos'!$A:$D,4,0),"") -> KG | F2: Cozinha de Produção de Fracionados | G2: 25 | H2: =IFERROR(SUMIF('Entrada na Central'!$C:$C,C2,'Entrada na Central'!$G:$G)-SUMIF($C:$C,C2,$G:$G)+G2,0) -> 40 | I2: Igor Morgado
A3: 46207 | B3: SC-002 | C3: BR-002 | D3: =IFERROR(VLOOKUP(C3,'Cadastro Produtos Brutos'!$A:$B,2,0),"") -> Arroz Japonês | E3: =IFERROR(VLOOKUP(C3,'Cadastro Produtos Brutos'!$A:$D,4,0),"") -> KG | F3: Cozinha de Produção de Fracionados | G3: 20 | H3: =IFERROR(SUMIF('Entrada na Central'!$C:$C,C3,'Entrada na Central'!$G:$G)-SUMIF($C:$C,C3,$G:$G)+G3,0) -> 30 | I3: Igor Morgado
A4: 46208 | B4: SC-003 | C4: BR-004 | D4: =IFERROR(VLOOKUP(C4,'Cadastro Produtos Brutos'!$A:$B,2,0),"") -> Filé de Frango | E4: =IFERROR(VLOOKUP(C4,'Cadastro Produtos Brutos'!$A:$D,4,0),"") -> KG | F4: Restaurante Arboreto | G4: 15 | H4: =IFERROR(SUMIF('Entrada na Central'!$C:$C,C4,'Entrada na Central'!$G:$G)-SUMIF($C:$C,C4,$G:$G)+G4,0) -> 20 | I4: Igor Morgado | J4: Envio direto, sem fracionar
A5: 46208 | B5: SC-004 | C5: BR-005 | D5: =IFERROR(VLOOKUP(C5,'Cadastro Produtos Brutos'!$A:$B,2,0),"") -> Tomate | E5: =IFERROR(VLOOKUP(C5,'Cadastro Produtos Brutos'!$A:$D,4,0),"") -> KG | F5: Cozinha de Produção de Fracionados | G5: 12 | H5: =IFERROR(SUMIF('Entrada na Central'!$C:$C,C5,'Entrada na Central'!$G:$G)-SUMIF($C:$C,C5,$G:$G)+G5,0) -> 20 | I5: Igor Morgado
A6: 46209 | B6: SC-005 | C6: BR-003 | D6: =IFERROR(VLOOKUP(C6,'Cadastro Produtos Brutos'!$A:$B,2,0),"") -> Alface Americana | E6: =IFERROR(VLOOKUP(C6,'Cadastro Produtos Brutos'!$A:$D,4,0),"") -> UN | F6: Cozinha de Produção de Fracionados | G6: 10 | H6: =IFERROR(SUMIF('Entrada na Central'!$C:$C,C6,'Entrada na Central'!$G:$G)-SUMIF($C:$C,C6,$G:$G)+G6,0) -> 15 | I6: Igor Morgado
A7: 46209 | B7: SC-006 | C7: BR-004 | D7: =IFERROR(VLOOKUP(C7,'Cadastro Produtos Brutos'!$A:$B,2,0),"") -> Filé de Frango | E7: =IFERROR(VLOOKUP(C7,'Cadastro Produtos Brutos'!$A:$D,4,0),"") -> KG | F7: Buffet Fran Casaria | G7: 5 | H7: =IFERROR(SUMIF('Entrada na Central'!$C:$C,C7,'Entrada na Central'!$G:$G)-SUMIF($C:$C,C7,$G:$G)+G7,0) -> 10 | I7: Igor Morgado | J7: Envio direto, sem fracionar

Sheet Produção de Fracionados
A1: Data | B1: Nº Lote de Produção | C1: Código Produto Fracionado Resultante | D1: Nome do Fracionado | E1: Código Produto Bruto Utilizado | F1: Nome do Bruto | G1: Quantidade Utilizada | H1: Unidade | I1: Saldo do Bruto na Cozinha Antes desta Produção | J1: Responsável | K1: Observações
A2: 46209 | B2: LP-001 | C2: FR-001 | D2: =IFERROR(VLOOKUP(C2,'Cadastro Produtos Fracionados'!$A:$B,2,0),"") -> Salmão Fatiado para Sushi | E2: BR-001 | F2: =IFERROR(VLOOKUP(E2,'Cadastro Produtos Brutos'!$A:$B,2,0),"") -> Salmão Fresco | G2: 20 | H2: =IFERROR(VLOOKUP(E2,'Cadastro Produtos Brutos'!$A:$D,4,0),"") -> KG | I2: =IFERROR(SUMIFS('Saída da Central'!$G:$G,'Saída da Central'!$C:$C,E2,'Saída da Central'!$F:$F,"Cozinha de Produção de Fracionados")-SUMIF($E:$E,E2,$G:$G)+G2,0) -> 25 | J2: Igor Morgado | K2: Fatiamento de salmão
A3: 46209 | B3: LP-002 | C3: FR-002 | D3: =IFERROR(VLOOKUP(C3,'Cadastro Produtos Fracionados'!$A:$B,2,0),"") -> Arroz Temperado para Sushi | E3: BR-002 | F3: =IFERROR(VLOOKUP(E3,'Cadastro Produtos Brutos'!$A:$B,2,0),"") -> Arroz Japonês | G3: 18 | H3: =IFERROR(VLOOKUP(E3,'Cadastro Produtos Brutos'!$A:$D,4,0),"") -> KG | I3: =IFERROR(SUMIFS('Saída da Central'!$G:$G,'Saída da Central'!$C:$C,E3,'Saída da Central'!$F:$F,"Cozinha de Produção de Fracionados")-SUMIF($E:$E,E3,$G:$G)+G3,0) -> 20 | J3: Igor Morgado | K3: Cozimento e tempero do arroz
A4: 46209 | B4: LP-003 | C4: FR-003 | D4: =IFERROR(VLOOKUP(C4,'Cadastro Produtos Fracionados'!$A:$B,2,0),"") -> Alface Higienizada e Cortada | E4: BR-003 | F4: =IFERROR(VLOOKUP(E4,'Cadastro Produtos Brutos'!$A:$B,2,0),"") -> Alface Americana | G4: 10 | H4: =IFERROR(VLOOKUP(E4,'Cadastro Produtos Brutos'!$A:$D,4,0),"") -> UN | I4: =IFERROR(SUMIFS('Saída da Central'!$G:$G,'Saída da Central'!$C:$C,E4,'Saída da Central'!$F:$F,"Cozinha de Produção de Fracionados")-SUMIF($E:$E,E4,$G:$G)+G4,0) -> 10 | J4: Igor Morgado | K4: Higienização e corte da alface
A5: 46209 | B5: LP-004 | C5: FR-005 | D5: =IFERROR(VLOOKUP(C5,'Cadastro Produtos Fracionados'!$A:$B,2,0),"") -> Tomate Picado | E5: BR-005 | F5: =IFERROR(VLOOKUP(E5,'Cadastro Produtos Brutos'!$A:$B,2,0),"") -> Tomate | G5: 12 | H5: =IFERROR(VLOOKUP(E5,'Cadastro Produtos Brutos'!$A:$D,4,0),"") -> KG | I5: =IFERROR(SUMIFS('Saída da Central'!$G:$G,'Saída da Central'!$C:$C,E5,'Saída da Central'!$F:$F,"Cozinha de Produção de Fracionados")-SUMIF($E:$E,E5,$G:$G)+G5,0) -> 12 | J5: Igor Morgado | K5: Corte do tomate

Sheet Entrada Estoque Fracionado
A1: Data da Produção | B1: Nº Lote de Produção | C1: Código Produto Fracionado | D1: Nome do Fracionado | E1: Quantidade Produzida (Rendimento) | F1: Unidade | G1: Validade Padrão (dias) | H1: Data de Validade | I1: Local de Armazenamento | J1: Responsável | K1: Observações
A2: 46209 | B2: LP-001 | C2: FR-001 | D2: =IFERROR(VLOOKUP(C2,'Cadastro Produtos Fracionados'!$A:$B,2,0),"") -> Salmão Fatiado para Sushi | E2: 17 | F2: =IFERROR(VLOOKUP(C2,'Cadastro Produtos Fracionados'!$A:$D,4,0),"") -> KG | G2: =IFERROR(VLOOKUP(C2,'Cadastro Produtos Fracionados'!$A:$J,10,0),"") -> 2 | H2: =IF(A2="","",A2+G2) -> 46211 | I2: Cozinha de Produção de Fracionados | J2: Igor Morgado | K2: Rendimento de 20kg de salmão bruto
A3: 46209 | B3: LP-002 | C3: FR-002 | D3: =IFERROR(VLOOKUP(C3,'Cadastro Produtos Fracionados'!$A:$B,2,0),"") -> Arroz Temperado para Sushi | E3: 22 | F3: =IFERROR(VLOOKUP(C3,'Cadastro Produtos Fracionados'!$A:$D,4,0),"") -> KG | G3: =IFERROR(VLOOKUP(C3,'Cadastro Produtos Fracionados'!$A:$J,10,0),"") -> 2 | H3: =IF(A3="","",A3+G3) -> 46211 | I3: Cozinha de Produção de Fracionados | J3: Igor Morgado | K3: Ganho de peso por hidratação do tempero
A4: 46209 | B4: LP-003 | C4: FR-003 | D4: =IFERROR(VLOOKUP(C4,'Cadastro Produtos Fracionados'!$A:$B,2,0),"") -> Alface Higienizada e Cortada | E4: 8 | F4: =IFERROR(VLOOKUP(C4,'Cadastro Produtos Fracionados'!$A:$D,4,0),"") -> KG | G4: =IFERROR(VLOOKUP(C4,'Cadastro Produtos Fracionados'!$A:$J,10,0),"") -> 3 | H4: =IF(A4="","",A4+G4) -> 46212 | I4: Cozinha de Produção de Fracionados | J4: Igor Morgado | K4: Perda por aparas na higienização
A5: 46209 | B5: LP-004 | C5: FR-005 | D5: =IFERROR(VLOOKUP(C5,'Cadastro Produtos Fracionados'!$A:$B,2,0),"") -> Tomate Picado | E5: 11 | F5: =IFERROR(VLOOKUP(C5,'Cadastro Produtos Fracionados'!$A:$D,4,0),"") -> KG | G5: =IFERROR(VLOOKUP(C5,'Cadastro Produtos Fracionados'!$A:$J,10,0),"") -> 2 | H5: =IF(A5="","",A5+G5) -> 46211 | I5: Cozinha de Produção de Fracionados | J5: Igor Morgado | K5: Perda por aparas no corte

Sheet Saída Estoque Fracionado
A1: Data | B1: Nº Documento | C1: Código Produto Fracionado | D1: Nome do Fracionado | E1: Unidade | F1: Local de Destino | G1: Quantidade | H1: Saldo Disponível Antes desta Saída | I1: Responsável | J1: Observações
A2: 46210 | B2: SF-001 | C2: FR-001 | D2: =IFERROR(VLOOKUP(C2,'Cadastro Produtos Fracionados'!$A:$B,2,0),"") -> Salmão Fatiado para Sushi | E2: =IFERROR(VLOOKUP(C2,'Cadastro Produtos Fracionados'!$A:$D,4,0),"") -> KG | F2: Sushi | G2: 10 | H2: =IFERROR(SUMIF('Entrada Estoque Fracionado'!$C:$C,C2,'Entrada Estoque Fracionado'!$E:$E)-SUMIF($C:$C,C2,$G:$G)+G2,0) -> 17 | I2: Igor Morgado
A3: 46210 | B3: SF-002 | C3: FR-002 | D3: =IFERROR(VLOOKUP(C3,'Cadastro Produtos Fracionados'!$A:$B,2,0),"") -> Arroz Temperado para Sushi | E3: =IFERROR(VLOOKUP(C3,'Cadastro Produtos Fracionados'!$A:$D,4,0),"") -> KG | F3: Sushi | G3: 12 | H3: =IFERROR(SUMIF('Entrada Estoque Fracionado'!$C:$C,C3,'Entrada Estoque Fracionado'!$E:$E)-SUMIF($C:$C,C3,$G:$G)+G3,0) -> 22 | I3: Igor Morgado
A4: 46210 | B4: SF-003 | C4: FR-003 | D4: =IFERROR(VLOOKUP(C4,'Cadastro Produtos Fracionados'!$A:$B,2,0),"") -> Alface Higienizada e Cortada | E4: =IFERROR(VLOOKUP(C4,'Cadastro Produtos Fracionados'!$A:$D,4,0),"") -> KG | F4: Buffet Fran Casaria | G4: 5 | H4: =IFERROR(SUMIF('Entrada Estoque Fracionado'!$C:$C,C4,'Entrada Estoque Fracionado'!$E:$E)-SUMIF($C:$C,C4,$G:$G)+G4,0) -> 8 | I4: Igor Morgado
A5: 46210 | B5: SF-004 | C5: FR-005 | D5: =IFERROR(VLOOKUP(C5,'Cadastro Produtos Fracionados'!$A:$B,2,0),"") -> Tomate Picado | E5: =IFERROR(VLOOKUP(C5,'Cadastro Produtos Fracionados'!$A:$D,4,0),"") -> KG | F5: Restaurante Arboreto | G5: 6 | H5: =IFERROR(SUMIF('Entrada Estoque Fracionado'!$C:$C,C5,'Entrada Estoque Fracionado'!$E:$E)-SUMIF($C:$C,C5,$G:$G)+G5,0) -> 11 | I5: Igor Morgado

Sheet Movimentações Gerais
A1: Data | B1: Tipo de Movimentação | C1: Origem | D1: Destino | E1: Código do Produto | F1: Nome do Produto | G1: Quantidade | H1: Unidade | I1: Documento/Lote | J1: Responsável | K1: Observações
A2: ENTRADAS — CENTRAL DE DISTRIBUIÇÃO
A3: =IF('Entrada na Central'!A2="","",'Entrada na Central'!A2) -> 46204 | B3: =IF('Entrada na Central'!A2="","","Entrada Central") -> Entrada Central | C3: =IF('Entrada na Central'!A2="","",'Entrada na Central'!F2) -> Fornecedor Mar Azul | D3: =IF('Entrada na Central'!A2="","","Central de Distribuição") -> Central de Distribuição | E3: =IF('Entrada na Central'!A2="","",'Entrada na Central'!C2) -> BR-001 | F3: =IF('Entrada na Central'!A2="","",'Entrada na Central'!D2) -> Salmão Fresco | G3: =IF('Entrada na Central'!A2="","",'Entrada na Central'!G2) -> 40 | H3: =IF('Entrada na Central'!A2="","",'Entrada na Central'!E2) -> KG | I3: =IF('Entrada na Central'!A2="","",'Entrada na Central'!B2&" / "&'Entrada na Central'!J2) -> NF-1001 / L001 | J3: =IF('Entrada na Central'!A2="","",'Entrada na Central'!L2&"") -> Igor Morgado | K3: =IF('Entrada na Central'!A2="","",'Entrada na Central'!M2&"")
A4: =IF('Entrada na Central'!A3="","",'Entrada na Central'!A3) -> 46204 | B4: =IF('Entrada na Central'!A3="","","Entrada Central") -> Entrada Central | C4: =IF('Entrada na Central'!A3="","",'Entrada na Central'!F3) -> Fornecedor Grão Bom | D4: =IF('Entrada na Central'!A3="","","Central de Distribuição") -> Central de Distribuição | E4: =IF('Entrada na Central'!A3="","",'Entrada na Central'!C3) -> BR-002 | F4: =IF('Entrada na Central'!A3="","",'Entrada na Central'!D3) -> Arroz Japonês | G4: =IF('Entrada na Central'!A3="","",'Entrada na Central'!G3) -> 30 | H4: =IF('Entrada na Central'!A3="","",'Entrada na Central'!E3) -> KG | I4: =IF('Entrada na Central'!A3="","",'Entrada na Central'!B3&" / "&'Entrada na Central'!J3) -> NF-1002 / L002 | J4: =IF('Entrada na Central'!A3="","",'Entrada na Central'!L3&"") -> Igor Morgado | K4: =IF('Entrada na Central'!A3="","",'Entrada na Central'!M3&"")
A5: =IF('Entrada na Central'!A4="","",'Entrada na Central'!A4) -> 46205 | B5: =IF('Entrada na Central'!A4="","","Entrada Central") -> Entrada Central | C5: =IF('Entrada na Central'!A4="","",'Entrada na Central'!F4) -> Fornecedor Avícola Sul | D5: =IF('Entrada na Central'!A4="","","Central de Distribuição") -> Central de Distribuição | E5: =IF('Entrada na Central'!A4="","",'Entrada na Central'!C4) -> BR-004 | F5: =IF('Entrada na Central'!A4="","",'Entrada na Central'!D4) -> Filé de Frango | G5: =IF('Entrada na Central'!A4="","",'Entrada na Central'!G4) -> 25 | H5: =IF('Entrada na Central'!A4="","",'Entrada na Central'!E4) -> KG | I5: =IF('Entrada na Central'!A4="","",'Entrada na Central'!B4&" / "&'Entrada na Central'!J4) -> NF-1003 / L003 | J5: =IF('Entrada na Central'!A4="","",'Entrada na Central'!L4&"") -> Igor Morgado | K5: =IF('Entrada na Central'!A4="","",'Entrada na Central'!M4&"")
A6: =IF('Entrada na Central'!A5="","",'Entrada na Central'!A5) -> 46205 | B6: =IF('Entrada na Central'!A5="","","Entrada Central") -> Entrada Central | C6: =IF('Entrada na Central'!A5="","",'Entrada na Central'!F5) -> Fornecedor Horta Feliz | D6: =IF('Entrada na Central'!A5="","","Central de Distribuição") -> Central de Distribuição | E6: =IF('Entrada na Central'!A5="","",'Entrada na Central'!C5) -> BR-005 | F6: =IF('Entrada na Central'!A5="","",'Entrada na Central'!D5) -> Tomate | G6: =IF('Entrada na Central'!A5="","",'Entrada na Central'!G5) -> 20 | H6: =IF('Entrada na Central'!A5="","",'Entrada na Central'!E5) -> KG | I6: =IF('Entrada na Central'!A5="","",'Entrada na Central'!B5&" / "&'Entrada na Central'!J5) -> NF-1004 / L004 | J6: =IF('Entrada na Central'!A5="","",'Entrada na Central'!L5&"") -> Igor Morgado | K6: =IF('Entrada na Central'!A5="","",'Entrada na Central'!M5&"")
A7: =IF('Entrada na Central'!A6="","",'Entrada na Central'!A6) -> 46206 | B7: =IF('Entrada na Central'!A6="","","Entrada Central") -> Entrada Central | C7: =IF('Entrada na Central'!A6="","",'Entrada na Central'!F6) -> Fornecedor Horta Feliz | D7: =IF('Entrada na Central'!A6="","","Central de Distribuição") -> Central de Distribuição | E7: =IF('Entrada na Central'!A6="","",'Entrada na Central'!C6) -> BR-003 | F7: =IF('Entrada na Central'!A6="","",'Entrada na Central'!D6) -> Alface Americana | G7: =IF('Entrada na Central'!A6="","",'Entrada na Central'!G6) -> 15 | H7: =IF('Entrada na Central'!A6="","",'Entrada na Central'!E6) -> UN | I7: =IF('Entrada na Central'!A6="","",'Entrada na Central'!B6&" / "&'Entrada na Central'!J6) -> NF-1005 / L005 | J7: =IF('Entrada na Central'!A6="","",'Entrada na Central'!L6&"") -> Igor Morgado | K7: =IF('Entrada na Central'!A6="","",'Entrada na Central'!M6&"")
A8: =IF('Entrada na Central'!A7="","",'Entrada na Central'!A7) | B8: =IF('Entrada na Central'!A7="","","Entrada Central") | C8: =IF('Entrada na Central'!A7="","",'Entrada na Central'!F7) | D8: =IF('Entrada na Central'!A7="","","Central de Distribuição") | E8: =IF('Entrada na Central'!A7="","",'Entrada na Central'!C7) | F8: =IF('Entrada na Central'!A7="","",'Entrada na Central'!D7) | G8: =IF('Entrada na Central'!A7="","",'Entrada na Central'!G7) | H8: =IF('Entrada na Central'!A7="","",'Entrada na Central'!E7) | I8: =IF('Entrada na Central'!A7="","",'Entrada na Central'!B7&" / "&'Entrada na Central'!J7) | J8: =IF('Entrada na Central'!A7="","",'Entrada na Central'!L7&"") | K8: =IF('Entrada na Central'!A7="","",'Entrada na Central'!M7&"")
A9: =IF('Entrada na Central'!A8="","",'Entrada na Central'!A8) | B9: =IF('Entrada na Central'!A8="","","Entrada Central") | C9: =IF('Entrada na Central'!A8="","",'Entrada na Central'!F8) | D9: =IF('Entrada na Central'!A8="","","Central de Distribuição") | E9: =IF('Entrada na Central'!A8="","",'Entrada na Central'!C8) | F9: =IF('Entrada na Central'!A8="","",'Entrada na Central'!D8) | G9: =IF('Entrada na Central'!A8="","",'Entrada na Central'!G8) | H9: =IF('Entrada na Central'!A8="","",'Entrada na Central'!E8) | I9: =IF('Entrada na Central'!A8="","",'Entrada na Central'!B8&" / "&'Entrada na Central'!J8) | J9: =IF('Entrada na Central'!A8="","",'Entrada na Central'!L8&"") | K9: =IF('Entrada na Central'!A8="","",'Entrada na Central'!M8&"")
A10: =IF('Entrada na Central'!A9="","",'Entrada na Central'!A9) | B10: =IF('Entrada na Central'!A9="","","Entrada Central") | C10: =IF('Entrada na Central'!A9="","",'Entrada na Central'!F9) | D10: =IF('Entrada na Central'!A9="","","Central de Distribuição") | E10: =IF('Entrada na Central'!A9="","",'Entrada na Central'!C9) | F10: =IF('Entrada na Central'!A9="","",'Entrada na Central'!D9) | G10: =IF('Entrada na Central'!A9="","",'Entrada na Central'!G9) | H10: =IF('Entrada na Central'!A9="","",'Entrada na Central'!E9) | I10: =IF('Entrada na Central'!A9="","",'Entrada na Central'!B9&" / "&'Entrada na Central'!J9) | J10: =IF('Entrada na Central'!A9="","",'Entrada na Central'!L9&"") | K10: =IF('Entrada na Central'!A9="","",'Entrada na Central'!M9&"")
A11: =IF('Entrada na Central'!A10="","",'Entrada na Central'!A10) | B11: =IF('Entrada na Central'!A10="","","Entrada Central") | C11: =IF('Entrada na Central'!A10="","",'Entrada na Central'!F10) | D11: =IF('Entrada na Central'!A10="","","Central de Distribuição") | E11: =IF('Entrada na Central'!A10="","",'Entrada na Central'!C10) | F11: =IF('Entrada na Central'!A10="","",'Entrada na Central'!D10) | G11: =IF('Entrada na Central'!A10="","",'Entrada na Central'!G10) | H11: =IF('Entrada na Central'!A10="","",'Entrada na Central'!E10) | I11: =IF('Entrada na Central'!A10="","",'Entrada na Central'!B10&" / "&'Entrada na Central'!J10) | J11: =IF('Entrada na Central'!A10="","",'Entrada na Central'!L10&"") | K11: =IF('Entrada na Central'!A10="","",'Entrada na Central'!M10&"")
A12: =IF('Entrada na Central'!A11="","",'Entrada na Central'!A11) | B12: =IF('Entrada na Central'!A11="","","Entrada Central") | C12: =IF('Entrada na Central'!A11="","",'Entrada na Central'!F11) | D12: =IF('Entrada na Central'!A11="","","Central de Distribuição") | E12: =IF('Entrada na Central'!A11="","",'Entrada na Central'!C11) | F12: =IF('Entrada na Central'!A11="","",'Entrada na Central'!D11) | G12: =IF('Entrada na Central'!A11="","",'Entrada na Central'!G11) | H12: =IF('Entrada na Central'!A11="","",'Entrada na Central'!E11) | I12: =IF('Entrada na Central'!A11="","",'Entrada na Central'!B11&" / "&'Entrada na Central'!J11) | J12: =IF('Entrada na Central'!A11="","",'Entrada na Central'!L11&"") | K12: =IF('Entrada na Central'!A11="","",'Entrada na Central'!M11&"")
A13: =IF('Entrada na Central'!A12="","",'Entrada na Central'!A12) | B13: =IF('Entrada na Central'!A12="","","Entrada Central") | C13: =IF('Entrada na Central'!A12="","",'Entrada na Central'!F12) | D13: =IF('Entrada na Central'!A12="","","Central de Distribuição") | E13: =IF('Entrada na Central'!A12="","",'Entrada na Central'!C12) | F13: =IF('Entrada na Central'!A12="","",'Entrada na Central'!D12) | G13: =IF('Entrada na Central'!A12="","",'Entrada na Central'!G12) | H13: =IF('Entrada na Central'!A12="","",'Entrada na Central'!E12) | I13: =IF('Entrada na Central'!A12="","",'Entrada na Central'!B12&" / "&'Entrada na Central'!J12) | J13: =IF('Entrada na Central'!A12="","",'Entrada na Central'!L12&"") | K13: =IF('Entrada na Central'!A12="","",'Entrada na Central'!M12&"")
A14: =IF('Entrada na Central'!A13="","",'Entrada na Central'!A13) | B14: =IF('Entrada na Central'!A13="","","Entrada Central") | C14: =IF('Entrada na Central'!A13="","",'Entrada na Central'!F13) | D14: =IF('Entrada na Central'!A13="","","Central de Distribuição") | E14: =IF('Entrada na Central'!A13="","",'Entrada na Central'!C13) | F14: =IF('Entrada na Central'!A13="","",'Entrada na Central'!D13) | G14: =IF('Entrada na Central'!A13="","",'Entrada na Central'!G13) | H14: =IF('Entrada na Central'!A13="","",'Entrada na Central'!E13) | I14: =IF('Entrada na Central'!A13="","",'Entrada na Central'!B13&" / "&'Entrada na Central'!J13) | J14: =IF('Entrada na Central'!A13="","",'Entrada na Central'!L13&"") | K14: =IF('Entrada na Central'!A13="","",'Entrada na Central'!M13&"")
... A32: =IF('Entrada na Central'!A31="","",'Entrada na Central'!A31) | B32: =IF('Entrada na Central'!A31="","","Entrada Central") | C32: =IF('Entrada na Central'!A31="","",'Entrada na Central'!F31) | D32: =IF('Entrada na Central'!A31="","","Central de Distribuição") | E32: =IF('Entrada na Central'!A31="","",'Entrada na Central'!C31) | F32: =IF('Entrada na Central'!A31="","",'Entrada na Central'!D31) | G32: =IF('Entrada na Central'!A31="","",'Entrada na Central'!G31) | H32: =IF('Entrada na Central'!A31="","",'Entrada na Central'!E31) | I32: =IF('Entrada na Central'!A31="","",'Entrada na Central'!B31&" / "&'Entrada na Central'!J31) | J32: =IF('Entrada na Central'!A31="","",'Entrada na Central'!L31&"") | K32: =IF('Entrada na Central'!A31="","",'Entrada na Central'!M31&"")
A33: SAÍDAS — CENTRAL DE DISTRIBUIÇÃO
A34: =IF('Saída da Central'!A2="","",'Saída da Central'!A2) -> 46207 | B34: =IF('Saída da Central'!A2="","","Saída Central") -> Saída Central | C34: =IF('Saída da Central'!A2="","","Central de Distribuição") -> Central de Distribuição | D34: =IF('Saída da Central'!A2="","",'Saída da Central'!F2) -> Cozinha de Produção de Fracionados | E34: =IF('Saída da Central'!A2="","",'Saída da Central'!C2) -> BR-001 | F34: =IF('Saída da Central'!A2="","",'Saída da Central'!D2) -> Salmão Fresco | G34: =IF('Saída da Central'!A2="","",'Saída da Central'!G2) -> 25 | H34: =IF('Saída da Central'!A2="","",'Saída da Central'!E2) -> KG | I34: =IF('Saída da Central'!A2="","",'Saída da Central'!B2) -> SC-001 | J34: =IF('Saída da Central'!A2="","",'Saída da Central'!I2&"") -> Igor Morgado | K34: =IF('Saída da Central'!A2="","",'Saída da Central'!J2&"")
A35: =IF('Saída da Central'!A3="","",'Saída da Central'!A3) -> 46207 | B35: =IF('Saída da Central'!A3="","","Saída Central") -> Saída Central | C35: =IF('Saída da Central'!A3="","","Central de Distribuição") -> Central de Distribuição | D35: =IF('Saída da Central'!A3="","",'Saída da Central'!F3) -> Cozinha de Produção de Fracionados | E35: =IF('Saída da Central'!A3="","",'Saída da Central'!C3) -> BR-002 | F35: =IF('Saída da Central'!A3="","",'Saída da Central'!D3) -> Arroz Japonês | G35: =IF('Saída da Central'!A3="","",'Saída da Central'!G3) -> 20 | H35: =IF('Saída da Central'!A3="","",'Saída da Central'!E3) -> KG | I35: =IF('Saída da Central'!A3="","",'Saída da Central'!B3) -> SC-002 | J35: =IF('Saída da Central'!A3="","",'Saída da Central'!I3&"") -> Igor Morgado | K35: =IF('Saída da Central'!A3="","",'Saída da Central'!J3&"")
A36: =IF('Saída da Central'!A4="","",'Saída da Central'!A4) -> 46208 | B36: =IF('Saída da Central'!A4="","","Saída Central") -> Saída Central | C36: =IF('Saída da Central'!A4="","","Central de Distribuição") -> Central de Distribuição | D36: =IF('Saída da Central'!A4="","",'Saída da Central'!F4) -> Restaurante Arboreto | E36: =IF('Saída da Central'!A4="","",'Saída da Central'!C4) -> BR-004 | F36: =IF('Saída da Central'!A4="","",'Saída da Central'!D4) -> Filé de Frango | G36: =IF('Saída da Central'!A4="","",'Saída da Central'!G4) -> 15 | H36: =IF('Saída da Central'!A4="","",'Saída da Central'!E4) -> KG | I36: =IF('Saída da Central'!A4="","",'Saída da Central'!B4) -> SC-003 | J36: =IF('Saída da Central'!A4="","",'Saída da Central'!I4&"") -> Igor Morgado | K36: =IF('Saída da Central'!A4="","",'Saída da Central'!J4&"") -> Envio direto, sem fracionar
A37: =IF('Saída da Central'!A5="","",'Saída da Central'!A5) -> 46208 | B37: =IF('Saída da Central'!A5="","","Saída Central") -> Saída Central | C37: =IF('Saída da Central'!A5="","","Central de Distribuição") -> Central de Distribuição | D37: =IF('Saída da Central'!A5="","",'Saída da Central'!F5) -> Cozinha de Produção de Fracionados | E37: =IF('Saída da Central'!A5="","",'Saída da Central'!C5) -> BR-005 | F37: =IF('Saída da Central'!A5="","",'Saída da Central'!D5) -> Tomate | G37: =IF('Saída da Central'!A5="","",'Saída da Central'!G5) -> 12 | H37: =IF('Saída da Central'!A5="","",'Saída da Central'!E5) -> KG | I37: =IF('Saída da Central'!A5="","",'Saída da Central'!B5) -> SC-004 | J37: =IF('Saída da Central'!A5="","",'Saída da Central'!I5&"") -> Igor Morgado | K37: =IF('Saída da Central'!A5="","",'Saída da Central'!J5&"")
A38: =IF('Saída da Central'!A6="","",'Saída da Central'!A6) -> 46209 | B38: =IF('Saída da Central'!A6="","","Saída Central") -> Saída Central | C38: =IF('Saída da Central'!A6="","","Central de Distribuição") -> Central de Distribuição | D38: =IF('Saída da Central'!A6="","",'Saída da Central'!F6) -> Cozinha de Produção de Fracionados | E38: =IF('Saída da Central'!A6="","",'Saída da Central'!C6) -> BR-003 | F38: =IF('Saída da Central'!A6="","",'Saída da Central'!D6) -> Alface Americana | G38: =IF('Saída da Central'!A6="","",'Saída da Central'!G6) -> 10 | H38: =IF('Saída da Central'!A6="","",'Saída da Central'!E6) -> UN | I38: =IF('Saída da Central'!A6="","",'Saída da Central'!B6) -> SC-005 | J38: =IF('Saída da Central'!A6="","",'Saída da Central'!I6&"") -> Igor Morgado | K38: =IF('Saída da Central'!A6="","",'Saída da Central'!J6&"")
A39: =IF('Saída da Central'!A7="","",'Saída da Central'!A7) -> 46209 | B39: =IF('Saída da Central'!A7="","","Saída Central") -> Saída Central | C39: =IF('Saída da Central'!A7="","","Central de Distribuição") -> Central de Distribuição | D39: =IF('Saída da Central'!A7="","",'Saída da Central'!F7) -> Buffet Fran Casaria | E39: =IF('Saída da Central'!A7="","",'Saída da Central'!C7) -> BR-004 | F39: =IF('Saída da Central'!A7="","",'Saída da Central'!D7) -> Filé de Frango | G39: =IF('Saída da Central'!A7="","",'Saída da Central'!G7) -> 5 | H39: =IF('Saída da Central'!A7="","",'Saída da Central'!E7) -> KG | I39: =IF('Saída da Central'!A7="","",'Saída da Central'!B7) -> SC-006 | J39: =IF('Saída da Central'!A7="","",'Saída da Central'!I7&"") -> Igor Morgado | K39: =IF('Saída da Central'!A7="","",'Saída da Central'!J7&"") -> Envio direto, sem fracionar
A40: =IF('Saída da Central'!A8="","",'Saída da Central'!A8) | B40: =IF('Saída da Central'!A8="","","Saída Central") | C40: =IF('Saída da Central'!A8="","","Central de Distribuição") | D40: =IF('Saída da Central'!A8="","",'Saída da Central'!F8) | E40: =IF('Saída da Central'!A8="","",'Saída da Central'!C8) | F40: =IF('Saída da Central'!A8="","",'Saída da Central'!D8) | G40: =IF('Saída da Central'!A8="","",'Saída da Central'!G8) | H40: =IF('Saída da Central'!A8="","",'Saída da Central'!E8) | I40: =IF('Saída da Central'!A8="","",'Saída da Central'!B8) | J40: =IF('Saída da Central'!A8="","",'Saída da Central'!I8&"") | K40: =IF('Saída da Central'!A8="","",'Saída da Central'!J8&"")
A41: =IF('Saída da Central'!A9="","",'Saída da Central'!A9) | B41: =IF('Saída da Central'!A9="","","Saída Central") | C41: =IF('Saída da Central'!A9="","","Central de Distribuição") | D41: =IF('Saída da Central'!A9="","",'Saída da Central'!F9) | E41: =IF('Saída da Central'!A9="","",'Saída da Central'!C9) | F41: =IF('Saída da Central'!A9="","",'Saída da Central'!D9) | G41: =IF('Saída da Central'!A9="","",'Saída da Central'!G9) | H41: =IF('Saída da Central'!A9="","",'Saída da Central'!E9) | I41: =IF('Saída da Central'!A9="","",'Saída da Central'!B9) | J41: =IF('Saída da Central'!A9="","",'Saída da Central'!I9&"") | K41: =IF('Saída da Central'!A9="","",'Saída da Central'!J9&"")
A42: =IF('Saída da Central'!A10="","",'Saída da Central'!A10) | B42: =IF('Saída da Central'!A10="","","Saída Central") | C42: =IF('Saída da Central'!A10="","","Central de Distribuição") | D42: =IF('Saída da Central'!A10="","",'Saída da Central'!F10) | E42: =IF('Saída da Central'!A10="","",'Saída da Central'!C10) | F42: =IF('Saída da Central'!A10="","",'Saída da Central'!D10) | G42: =IF('Saída da Central'!A10="","",'Saída da Central'!G10) | H42: =IF('Saída da Central'!A10="","",'Saída da Central'!E10) | I42: =IF('Saída da Central'!A10="","",'Saída da Central'!B10) | J42: =IF('Saída da Central'!A10="","",'Saída da Central'!I10&"") | K42: =IF('Saída da Central'!A10="","",'Saída da Central'!J10&"")
A43: =IF('Saída da Central'!A11="","",'Saída da Central'!A11) | B43: =IF('Saída da Central'!A11="","","Saída Central") | C43: =IF('Saída da Central'!A11="","","Central de Distribuição") | D43: =IF('Saída da Central'!A11="","",'Saída da Central'!F11) | E43: =IF('Saída da Central'!A11="","",'Saída da Central'!C11) | F43: =IF('Saída da Central'!A11="","",'Saída da Central'!D11) | G43: =IF('Saída da Central'!A11="","",'Saída da Central'!G11) | H43: =IF('Saída da Central'!A11="","",'Saída da Central'!E11) | I43: =IF('Saída da Central'!A11="","",'Saída da Central'!B11) | J43: =IF('Saída da Central'!A11="","",'Saída da Central'!I11&"") | K43: =IF('Saída da Central'!A11="","",'Saída da Central'!J11&"")
A44: =IF('Saída da Central'!A12="","",'Saída da Central'!A12) | B44: =IF('Saída da Central'!A12="","","Saída Central") | C44: =IF('Saída da Central'!A12="","","Central de Distribuição") | D44: =IF('Saída da Central'!A12="","",'Saída da Central'!F12) | E44: =IF('Saída da Central'!A12="","",'Saída da Central'!C12) | F44: =IF('Saída da Central'!A12="","",'Saída da Central'!D12) | G44: =IF('Saída da Central'!A12="","",'Saída da Central'!G12) | H44: =IF('Saída da Central'!A12="","",'Saída da Central'!E12) | I44: =IF('Saída da Central'!A12="","",'Saída da Central'!B12) | J44: =IF('Saída da Central'!A12="","",'Saída da Central'!I12&"") | K44: =IF('Saída da Central'!A12="","",'Saída da Central'!J12&"")
A45: =IF('Saída da Central'!A13="","",'Saída da Central'!A13) | B45: =IF('Saída da Central'!A13="","","Saída Central") | C45: =IF('Saída da Central'!A13="","","Central de Distribuição") | D45: =IF('Saída da Central'!A13="","",'Saída da Central'!F13) | E45: =IF('Saída da Central'!A13="","",'Saída da Central'!C13) | F45: =IF('Saída da Central'!A13="","",'Saída da Central'!D13) | G45: =IF('Saída da Central'!A13="","",'Saída da Central'!G13) | H45: =IF('Saída da Central'!A13="","",'Saída da Central'!E13) | I45: =IF('Saída da Central'!A13="","",'Saída da Central'!B13) | J45: =IF('Saída da Central'!A13="","",'Saída da Central'!I13&"") | K45: =IF('Saída da Central'!A13="","",'Saída da Central'!J13&"")
... A63: =IF('Saída da Central'!A31="","",'Saída da Central'!A31) | B63: =IF('Saída da Central'!A31="","","Saída Central") | C63: =IF('Saída da Central'!A31="","","Central de Distribuição") | D63: =IF('Saída da Central'!A31="","",'Saída da Central'!F31) | E63: =IF('Saída da Central'!A31="","",'Saída da Central'!C31) | F63: =IF('Saída da Central'!A31="","",'Saída da Central'!D31) | G63: =IF('Saída da Central'!A31="","",'Saída da Central'!G31) | H63: =IF('Saída da Central'!A31="","",'Saída da Central'!E31) | I63: =IF('Saída da Central'!A31="","",'Saída da Central'!B31) | J63: =IF('Saída da Central'!A31="","",'Saída da Central'!I31&"") | K63: =IF('Saída da Central'!A31="","",'Saída da Central'!J31&"")
A64: PRODUÇÃO — CONSUMO DE BRUTO NA COZINHA DE FRACIONAMENTO
A65: =IF('Produção de Fracionados'!A2="","",'Produção de Fracionados'!A2) -> 46209 | B65: =IF('Produção de Fracionados'!A2="","","Produção (Consumo de Bruto)") -> Produção (Consumo de Bruto) | C65: =IF('Produção de Fracionados'!A2="","","Cozinha de Produção de Fracionados") -> Cozinha de Produção de Fracionados | D65: =IF('Produção de Fracionados'!A2="","",'Produção de Fracionados'!D2) -> Salmão Fatiado para Sushi | E65: =IF('Produção de Fracionados'!A2="","",'Produção de Fracionados'!E2) -> BR-001 | F65: =IF('Produção de Fracionados'!A2="","",'Produção de Fracionados'!F2) -> Salmão Fresco | G65: =IF('Produção de Fracionados'!A2="","",'Produção de Fracionados'!G2) -> 20 | H65: =IF('Produção de Fracionados'!A2="","",'Produção de Fracionados'!H2) -> KG | I65: =IF('Produção de Fracionados'!A2="","",'Produção de Fracionados'!B2) -> LP-001 | J65: =IF('Produção de Fracionados'!A2="","",'Produção de Fracionados'!J2&"") -> Igor Morgado | K65: =IF('Produção de Fracionados'!A2="","",'Produção de Fracionados'!K2&"") -> Fatiamento de salmão
A66: =IF('Produção de Fracionados'!A3="","",'Produção de Fracionados'!A3) -> 46209 | B66: =IF('Produção de Fracionados'!A3="","","Produção (Consumo de Bruto)") -> Produção (Consumo de Bruto) | C66: =IF('Produção de Fracionados'!A3="","","Cozinha de Produção de Fracionados") -> Cozinha de Produção de Fracionados | D66: =IF('Produção de Fracionados'!A3="","",'Produção de Fracionados'!D3) -> Arroz Temperado para Sushi | E66: =IF('Produção de Fracionados'!A3="","",'Produção de Fracionados'!E3) -> BR-002 | F66: =IF('Produção de Fracionados'!A3="","",'Produção de Fracionados'!F3) -> Arroz Japonês | G66: =IF('Produção de Fracionados'!A3="","",'Produção de Fracionados'!G3) -> 18 | H66: =IF('Produção de Fracionados'!A3="","",'Produção de Fracionados'!H3) -> KG | I66: =IF('Produção de Fracionados'!A3="","",'Produção de Fracionados'!B3) -> LP-002 | J66: =IF('Produção de Fracionados'!A3="","",'Produção de Fracionados'!J3&"") -> Igor Morgado | K66: =IF('Produção de Fracionados'!A3="","",'Produção de Fracionados'!K3&"") -> Cozimento e tempero do arroz
A67: =IF('Produção de Fracionados'!A4="","",'Produção de Fracionados'!A4) -> 46209 | B67: =IF('Produção de Fracionados'!A4="","","Produção (Consumo de Bruto)") -> Produção (Consumo de Bruto) | C67: =IF('Produção de Fracionados'!A4="","","Cozinha de Produção de Fracionados") -> Cozinha de Produção de Fracionados | D67: =IF('Produção de Fracionados'!A4="","",'Produção de Fracionados'!D4) -> Alface Higienizada e Cortada | E67: =IF('Produção de Fracionados'!A4="","",'Produção de Fracionados'!E4) -> BR-003 | F67: =IF('Produção de Fracionados'!A4="","",'Produção de Fracionados'!F4) -> Alface Americana | G67: =IF('Produção de Fracionados'!A4="","",'Produção de Fracionados'!G4) -> 10 | H67: =IF('Produção de Fracionados'!A4="","",'Produção de Fracionados'!H4) -> UN | I67: =IF('Produção de Fracionados'!A4="","",'Produção de Fracionados'!B4) -> LP-003 | J67: =IF('Produção de Fracionados'!A4="","",'Produção de Fracionados'!J4&"") -> Igor Morgado | K67: =IF('Produção de Fracionados'!A4="","",'Produção de Fracionados'!K4&"") -> Higienização e corte da alface
A68: =IF('Produção de Fracionados'!A5="","",'Produção de Fracionados'!A5) -> 46209 | B68: =IF('Produção de Fracionados'!A5="","","Produção (Consumo de Bruto)") -> Produção (Consumo de Bruto) | C68: =IF('Produção de Fracionados'!A5="","","Cozinha de Produção de Fracionados") -> Cozinha de Produção de Fracionados | D68: =IF('Produção de Fracionados'!A5="","",'Produção de Fracionados'!D5) -> Tomate Picado | E68: =IF('Produção de Fracionados'!A5="","",'Produção de Fracionados'!E5) -> BR-005 | F68: =IF('Produção de Fracionados'!A5="","",'Produção de Fracionados'!F5) -> Tomate | G68: =IF('Produção de Fracionados'!A5="","",'Produção de Fracionados'!G5) -> 12 | H68: =IF('Produção de Fracionados'!A5="","",'Produção de Fracionados'!H5) -> KG | I68: =IF('Produção de Fracionados'!A5="","",'Produção de Fracionados'!B5) -> LP-004 | J68: =IF('Produção de Fracionados'!A5="","",'Produção de Fracionados'!J5&"") -> Igor Morgado | K68: =IF('Produção de Fracionados'!A5="","",'Produção de Fracionados'!K5&"") -> Corte do tomate
A69: =IF('Produção de Fracionados'!A6="","",'Produção de Fracionados'!A6) | B69: =IF('Produção de Fracionados'!A6="","","Produção (Consumo de Bruto)") | C69: =IF('Produção de Fracionados'!A6="","","Cozinha de Produção de Fracionados") | D69: =IF('Produção de Fracionados'!A6="","",'Produção de Fracionados'!D6) | E69: =IF('Produção de Fracionados'!A6="","",'Produção de Fracionados'!E6) | F69: =IF('Produção de Fracionados'!A6="","",'Produção de Fracionados'!F6) | G69: =IF('Produção de Fracionados'!A6="","",'Produção de Fracionados'!G6) | H69: =IF('Produção de Fracionados'!A6="","",'Produção de Fracionados'!H6) | I69: =IF('Produção de Fracionados'!A6="","",'Produção de Fracionados'!B6) | J69: =IF('Produção de Fracionados'!A6="","",'Produção de Fracionados'!J6&"") | K69: =IF('Produção de Fracionados'!A6="","",'Produção de Fracionados'!K6&"")
A70: =IF('Produção de Fracionados'!A7="","",'Produção de Fracionados'!A7) | B70: =IF('Produção de Fracionados'!A7="","","Produção (Consumo de Bruto)") | C70: =IF('Produção de Fracionados'!A7="","","Cozinha de Produção de Fracionados") | D70: =IF('Produção de Fracionados'!A7="","",'Produção de Fracionados'!D7) | E70: =IF('Produção de Fracionados'!A7="","",'Produção de Fracionados'!E7) | F70: =IF('Produção de Fracionados'!A7="","",'Produção de Fracionados'!F7) | G70: =IF('Produção de Fracionados'!A7="","",'Produção de Fracionados'!G7) | H70: =IF('Produção de Fracionados'!A7="","",'Produção de Fracionados'!H7) | I70: =IF('Produção de Fracionados'!A7="","",'Produção de Fracionados'!B7) | J70: =IF('Produção de Fracionados'!A7="","",'Produção de Fracionados'!J7&"") | K70: =IF('Produção de Fracionados'!A7="","",'Produção de Fracionados'!K7&"")
A71: =IF('Produção de Fracionados'!A8="","",'Produção de Fracionados'!A8) | B71: =IF('Produção de Fracionados'!A8="","","Produção (Consumo de Bruto)") | C71: =IF('Produção de Fracionados'!A8="","","Cozinha de Produção de Fracionados") | D71: =IF('Produção de Fracionados'!A8="","",'Produção de Fracionados'!D8) | E71: =IF('Produção de Fracionados'!A8="","",'Produção de Fracionados'!E8) | F71: =IF('Produção de Fracionados'!A8="","",'Produção de Fracionados'!F8) | G71: =IF('Produção de Fracionados'!A8="","",'Produção de Fracionados'!G8) | H71: =IF('Produção de Fracionados'!A8="","",'Produção de Fracionados'!H8) | I71: =IF('Produção de Fracionados'!A8="","",'Produção de Fracionados'!B8) | J71: =IF('Produção de Fracionados'!A8="","",'Produção de Fracionados'!J8&"") | K71: =IF('Produção de Fracionados'!A8="","",'Produção de Fracionados'!K8&"")
A72: =IF('Produção de Fracionados'!A9="","",'Produção de Fracionados'!A9) | B72: =IF('Produção de Fracionados'!A9="","","Produção (Consumo de Bruto)") | C72: =IF('Produção de Fracionados'!A9="","","Cozinha de Produção de Fracionados") | D72: =IF('Produção de Fracionados'!A9="","",'Produção de Fracionados'!D9) | E72: =IF('Produção de Fracionados'!A9="","",'Produção de Fracionados'!E9) | F72: =IF('Produção de Fracionados'!A9="","",'Produção de Fracionados'!F9) | G72: =IF('Produção de Fracionados'!A9="","",'Produção de Fracionados'!G9) | H72: =IF('Produção de Fracionados'!A9="","",'Produção de Fracionados'!H9) | I72: =IF('Produção de Fracionados'!A9="","",'Produção de Fracionados'!B9) | J72: =IF('Produção de Fracionados'!A9="","",'Produção de Fracionados'!J9&"") | K72: =IF('Produção de Fracionados'!A9="","",'Produção de Fracionados'!K9&"")
A73: =IF('Produção de Fracionados'!A10="","",'Produção de Fracionados'!A10) | B73: =IF('Produção de Fracionados'!A10="","","Produção (Consumo de Bruto)") | C73: =IF('Produção de Fracionados'!A10="","","Cozinha de Produção de Fracionados") | D73: =IF('Produção de Fracionados'!A10="","",'Produção de Fracionados'!D10) | E73: =IF('Produção de Fracionados'!A10="","",'Produção de Fracionados'!E10) | F73: =IF('Produção de Fracionados'!A10="","",'Produção de Fracionados'!F10) | G73: =IF('Produção de Fracionados'!A10="","",'Produção de Fracionados'!G10) | H73: =IF('Produção de Fracionados'!A10="","",'Produção de Fracionados'!H10) | I73: =IF('Produção de Fracionados'!A10="","",'Produção de Fracionados'!B10) | J73: =IF('Produção de Fracionados'!A10="","",'Produção de Fracionados'!J10&"") | K73: =IF('Produção de Fracionados'!A10="","",'Produção de Fracionados'!K10&"")
A74: =IF('Produção de Fracionados'!A11="","",'Produção de Fracionados'!A11) | B74: =IF('Produção de Fracionados'!A11="","","Produção (Consumo de Bruto)") | C74: =IF('Produção de Fracionados'!A11="","","Cozinha de Produção de Fracionados") | D74: =IF('Produção de Fracionados'!A11="","",'Produção de Fracionados'!D11) | E74: =IF('Produção de Fracionados'!A11="","",'Produção de Fracionados'!E11) | F74: =IF('Produção de Fracionados'!A11="","",'Produção de Fracionados'!F11) | G74: =IF('Produção de Fracionados'!A11="","",'Produção de Fracionados'!G11) | H74: =IF('Produção de Fracionados'!A11="","",'Produção de Fracionados'!H11) | I74: =IF('Produção de Fracionados'!A11="","",'Produção de Fracionados'!B11) | J74: =IF('Produção de Fracionados'!A11="","",'Produção de Fracionados'!J11&"") | K74: =IF('Produção de Fracionados'!A11="","",'Produção de Fracionados'!K11&"")
...

Sheet Estoque Atual por Produto
A1: ESTOQUE ATUAL — PRODUTOS BRUTOS (SALDO NA CENTRAL DE DISTRIBUIÇÃO)
A2: Código | B2: Nome do Produto | C2: Unidade | D2: Total Entradas | E2: Total Saídas | F2: Saldo Atual | G2: Estoque Mínimo | H2: Estoque Máximo | I2: Status
A3: ='Cadastro Produtos Brutos'!A2 -> BR-001 | B3: ='Cadastro Produtos Brutos'!B2 -> Salmão Fresco | C3: ='Cadastro Produtos Brutos'!D2 -> KG | D3: =SUMIF('Entrada na Central'!$C:$C,A3,'Entrada na Central'!$G:$G) -> 40 | E3: =SUMIF('Saída da Central'!$C:$C,A3,'Saída da Central'!$G:$G) -> 25 | F3: =D3-E3 -> 15 | G3: ='Cadastro Produtos Brutos'!E2 -> 5 | H3: ='Cadastro Produtos Brutos'!F2 -> 50 | I3: =IF(F3<=G3,"⚠ ABAIXO DO MÍNIMO",IF(F3>=H3,"▲ ACIMA DO MÁXIMO","✓ NORMAL")) -> ✓ NORMAL
A4: ='Cadastro Produtos Brutos'!A3 -> BR-002 | B4: ='Cadastro Produtos Brutos'!B3 -> Arroz Japonês | C4: ='Cadastro Produtos Brutos'!D3 -> KG | D4: =SUMIF('Entrada na Central'!$C:$C,A4,'Entrada na Central'!$G:$G) -> 30 | E4: =SUMIF('Saída da Central'!$C:$C,A4,'Saída da Central'!$G:$G) -> 20 | F4: =D4-E4 -> 10 | G4: ='Cadastro Produtos Brutos'!E3 -> 10 | H4: ='Cadastro Produtos Brutos'!F3 -> 100 | I4: =IF(F4<=G4,"⚠ ABAIXO DO MÍNIMO",IF(F4>=H4,"▲ ACIMA DO MÁXIMO","✓ NORMAL")) -> ⚠ ABAIXO DO MÍNIMO
A5: ='Cadastro Produtos Brutos'!A4 -> BR-003 | B5: ='Cadastro Produtos Brutos'!B4 -> Alface Americana | C5: ='Cadastro Produtos Brutos'!D4 -> UN | D5: =SUMIF('Entrada na Central'!$C:$C,A5,'Entrada na Central'!$G:$G) -> 15 | E5: =SUMIF('Saída da Central'!$C:$C,A5,'Saída da Central'!$G:$G) -> 10 | F5: =D5-E5 -> 5 | G5: ='Cadastro Produtos Brutos'!E4 -> 5 | H5: ='Cadastro Produtos Brutos'!F4 -> 40 | I5: =IF(F5<=G5,"⚠ ABAIXO DO MÍNIMO",IF(F5>=H5,"▲ ACIMA DO MÁXIMO","✓ NORMAL")) -> ⚠ ABAIXO DO MÍNIMO
A6: ='Cadastro Produtos Brutos'!A5 -> BR-004 | B6: ='Cadastro Produtos Brutos'!B5 -> Filé de Frango | C6: ='Cadastro Produtos Brutos'!D5 -> KG | D6: =SUMIF('Entrada na Central'!$C:$C,A6,'Entrada na Central'!$G:$G) -> 25 | E6: =SUMIF('Saída da Central'!$C:$C,A6,'Saída da Central'!$G:$G) -> 20 | F6: =D6-E6 -> 5 | G6: ='Cadastro Produtos Brutos'!E5 -> 8 | H6: ='Cadastro Produtos Brutos'!F5 -> 60 | I6: =IF(F6<=G6,"⚠ ABAIXO DO MÍNIMO",IF(F6>=H6,"▲ ACIMA DO MÁXIMO","✓ NORMAL")) -> ⚠ ABAIXO DO MÍNIMO
A7: ='Cadastro Produtos Brutos'!A6 -> BR-005 | B7: ='Cadastro Produtos Brutos'!B6 -> Tomate | C7: ='Cadastro Produtos Brutos'!D6 -> KG | D7: =SUMIF('Entrada na Central'!$C:$C,A7,'Entrada na Central'!$G:$G) -> 20 | E7: =SUMIF('Saída da Central'!$C:$C,A7,'Saída da Central'!$G:$G) -> 12 | F7: =D7-E7 -> 8 | G7: ='Cadastro Produtos Brutos'!E6 -> 5 | H7: ='Cadastro Produtos Brutos'!F6 -> 40 | I7: =IF(F7<=G7,"⚠ ABAIXO DO MÍNIMO",IF(F7>=H7,"▲ ACIMA DO MÁXIMO","✓ NORMAL")) -> ✓ NORMAL
A8: ='Cadastro Produtos Brutos'!A7 -> BR-006 | B8: ='Cadastro Produtos Brutos'!B7 -> Queijo Muçarela | C8: ='Cadastro Produtos Brutos'!D7 -> KG | D8: =SUMIF('Entrada na Central'!$C:$C,A8,'Entrada na Central'!$G:$G) -> 0 | E8: =SUMIF('Saída da Central'!$C:$C,A8,'Saída da Central'!$G:$G) -> 0 | F8: =D8-E8 -> 0 | G8: ='Cadastro Produtos Brutos'!E7 -> 5 | H8: ='Cadastro Produtos Brutos'!F7 -> 30 | I8: =IF(F8<=G8,"⚠ ABAIXO DO MÍNIMO",IF(F8>=H8,"▲ ACIMA DO MÁXIMO","✓ NORMAL")) -> ⚠ ABAIXO DO MÍNIMO
A10: ESTOQUE ATUAL — PRODUTOS FRACIONADOS (SALDO NA COZINHA DE PRODUÇÃO DE FRACIONADOS)
A11: Código | B11: Nome do Produto | C11: Unidade | D11: Total Produzido | E11: Total Distribuído | F11: Saldo Atual | G11: Estoque Mínimo | H11: Estoque Máximo | I11: Status
A12: ='Cadastro Produtos Fracionados'!A2 -> FR-001 | B12: ='Cadastro Produtos Fracionados'!B2 -> Salmão Fatiado para Sushi | C12: ='Cadastro Produtos Fracionados'!D2 -> KG | D12: =SUMIF('Entrada Estoque Fracionado'!$C:$C,A12,'Entrada Estoque Fracionado'!$E:$E) -> 17 | E12: =SUMIF('Saída Estoque Fracionado'!$C:$C,A12,'Saída Estoque Fracionado'!$G:$G) -> 10 | F12: =D12-E12 -> 7 | G12: ='Cadastro Produtos Fracionados'!H2 -> 2 | H12: ='Cadastro Produtos Fracionados'!I2 -> 20 | I12: =IF(F12<=G12,"⚠ ABAIXO DO MÍNIMO",IF(F12>=H12,"▲ ACIMA DO MÁXIMO","✓ NORMAL")) -> ✓ NORMAL
A13: ='Cadastro Produtos Fracionados'!A3 -> FR-002 | B13: ='Cadastro Produtos Fracionados'!B3 -> Arroz Temperado para Sushi | C13: ='Cadastro Produtos Fracionados'!D3 -> KG | D13: =SUMIF('Entrada Estoque Fracionado'!$C:$C,A13,'Entrada Estoque Fracionado'!$E:$E) -> 22 | E13: =SUMIF('Saída Estoque Fracionado'!$C:$C,A13,'Saída Estoque Fracionado'!$G:$G) -> 12 | F13: =D13-E13 -> 10 | G13: ='Cadastro Produtos Fracionados'!H3 -> 3 | H13: ='Cadastro Produtos Fracionados'!I3 -> 25 | I13: =IF(F13<=G13,"⚠ ABAIXO DO MÍNIMO",IF(F13>=H13,"▲ ACIMA DO MÁXIMO","✓ NORMAL")) -> ✓ NORMAL
A14: ='Cadastro Produtos Fracionados'!A4 -> FR-003 | B14: ='Cadastro Produtos Fracionados'!B4 -> Alface Higienizada e Cortada | C14: ='Cadastro Produtos Fracionados'!D4 -> KG | D14: =SUMIF('Entrada Estoque Fracionado'!$C:$C,A14,'Entrada Estoque Fracionado'!$E:$E) -> 8 | E14: =SUMIF('Saída Estoque Fracionado'!$C:$C,A14,'Saída Estoque Fracionado'!$G:$G) -> 5 | F14: =D14-E14 -> 3 | G14: ='Cadastro Produtos Fracionados'!H4 -> 2 | H14: ='Cadastro Produtos Fracionados'!I4 -> 15 | I14: =IF(F14<=G14,"⚠ ABAIXO DO MÍNIMO",IF(F14>=H14,"▲ ACIMA DO MÁXIMO","✓ NORMAL")) -> ✓ NORMAL
A15: ='Cadastro Produtos Fracionados'!A5 -> FR-004 | B15: ='Cadastro Produtos Fracionados'!B5 -> Frango Grelhado em Cubos | C15: ='Cadastro Produtos Fracionados'!D5 -> KG | D15: =SUMIF('Entrada Estoque Fracionado'!$C:$C,A15,'Entrada Estoque Fracionado'!$E:$E) -> 0 | E15: =SUMIF('Saída Estoque Fracionado'!$C:$C,A15,'Saída Estoque Fracionado'!$G:$G) -> 0 | F15: =D15-E15 -> 0 | G15: ='Cadastro Produtos Fracionados'!H5 -> 2 | H15: ='Cadastro Produtos Fracionados'!I5 -> 15 | I15: =IF(F15<=G15,"⚠ ABAIXO DO MÍNIMO",IF(F15>=H15,"▲ ACIMA DO MÁXIMO","✓ NORMAL")) -> ⚠ ABAIXO DO MÍNIMO
A16: ='Cadastro Produtos Fracionados'!A6 -> FR-005 | B16: ='Cadastro Produtos Fracionados'!B6 -> Tomate Picado | C16: ='Cadastro Produtos Fracionados'!D6 -> KG | D16: =SUMIF('Entrada Estoque Fracionado'!$C:$C,A16,'Entrada Estoque Fracionado'!$E:$E) -> 11 | E16: =SUMIF('Saída Estoque Fracionado'!$C:$C,A16,'Saída Estoque Fracionado'!$G:$G) -> 6 | F16: =D16-E16 -> 5 | G16: ='Cadastro Produtos Fracionados'!H6 -> 2 | H16: ='Cadastro Produtos Fracionados'!I6 -> 15 | I16: =IF(F16<=G16,"⚠ ABAIXO DO MÍNIMO",IF(F16>=H16,"▲ ACIMA DO MÁXIMO","✓ NORMAL")) -> ✓ NORMAL

Sheet Estoque Atual por Local
A1: Local | B1: Tipo de Produto | C1: Código do Produto | D1: Nome do Produto | E1: Unidade | F1: Saldo Atual | G1: Status
A2: Central de Distribuição | B2: Bruto | C2: ='Cadastro Produtos Brutos'!A2 -> BR-001 | D2: ='Cadastro Produtos Brutos'!B2 -> Salmão Fresco | E2: ='Cadastro Produtos Brutos'!D2 -> KG | F2: =SUMIF('Entrada na Central'!$C:$C,C2,'Entrada na Central'!$G:$G)-SUMIF('Saída da Central'!$C:$C,C2,'Saída da Central'!$G:$G) -> 15 | G2: =IF(F2<=('Cadastro Produtos Brutos'!E2),"⚠ ABAIXO DO MÍNIMO","✓ NORMAL") -> ✓ NORMAL
A3: Central de Distribuição | B3: Bruto | C3: ='Cadastro Produtos Brutos'!A3 -> BR-002 | D3: ='Cadastro Produtos Brutos'!B3 -> Arroz Japonês | E3: ='Cadastro Produtos Brutos'!D3 -> KG | F3: =SUMIF('Entrada na Central'!$C:$C,C3,'Entrada na Central'!$G:$G)-SUMIF('Saída da Central'!$C:$C,C3,'Saída da Central'!$G:$G) -> 10 | G3: =IF(F3<=('Cadastro Produtos Brutos'!E3),"⚠ ABAIXO DO MÍNIMO","✓ NORMAL") -> ⚠ ABAIXO DO MÍNIMO
A4: Central de Distribuição | B4: Bruto | C4: ='Cadastro Produtos Brutos'!A4 -> BR-003 | D4: ='Cadastro Produtos Brutos'!B4 -> Alface Americana | E4: ='Cadastro Produtos Brutos'!D4 -> UN | F4: =SUMIF('Entrada na Central'!$C:$C,C4,'Entrada na Central'!$G:$G)-SUMIF('Saída da Central'!$C:$C,C4,'Saída da Central'!$G:$G) -> 5 | G4: =IF(F4<=('Cadastro Produtos Brutos'!E4),"⚠ ABAIXO DO MÍNIMO","✓ NORMAL") -> ⚠ ABAIXO DO MÍNIMO
A5: Central de Distribuição | B5: Bruto | C5: ='Cadastro Produtos Brutos'!A5 -> BR-004 | D5: ='Cadastro Produtos Brutos'!B5 -> Filé de Frango | E5: ='Cadastro Produtos Brutos'!D5 -> KG | F5: =SUMIF('Entrada na Central'!$C:$C,C5,'Entrada na Central'!$G:$G)-SUMIF('Saída da Central'!$C:$C,C5,'Saída da Central'!$G:$G) -> 5 | G5: =IF(F5<=('Cadastro Produtos Brutos'!E5),"⚠ ABAIXO DO MÍNIMO","✓ NORMAL") -> ⚠ ABAIXO DO MÍNIMO
A6: Central de Distribuição | B6: Bruto | C6: ='Cadastro Produtos Brutos'!A6 -> BR-005 | D6: ='Cadastro Produtos Brutos'!B6 -> Tomate | E6: ='Cadastro Produtos Brutos'!D6 -> KG | F6: =SUMIF('Entrada na Central'!$C:$C,C6,'Entrada na Central'!$G:$G)-SUMIF('Saída da Central'!$C:$C,C6,'Saída da Central'!$G:$G) -> 8 | G6: =IF(F6<=('Cadastro Produtos Brutos'!E6),"⚠ ABAIXO DO MÍNIMO","✓ NORMAL") -> ✓ NORMAL
A7: Central de Distribuição | B7: Bruto | C7: ='Cadastro Produtos Brutos'!A7 -> BR-006 | D7: ='Cadastro Produtos Brutos'!B7 -> Queijo Muçarela | E7: ='Cadastro Produtos Brutos'!D7 -> KG | F7: =SUMIF('Entrada na Central'!$C:$C,C7,'Entrada na Central'!$G:$G)-SUMIF('Saída da Central'!$C:$C,C7,'Saída da Central'!$G:$G) -> 0 | G7: =IF(F7<=('Cadastro Produtos Brutos'!E7),"⚠ ABAIXO DO MÍNIMO","✓ NORMAL") -> ⚠ ABAIXO DO MÍNIMO
A8: Cozinha de Produção de Fracionados | B8: Bruto | C8: ='Cadastro Produtos Brutos'!A2 -> BR-001 | D8: ='Cadastro Produtos Brutos'!B2 -> Salmão Fresco | E8: ='Cadastro Produtos Brutos'!D2 -> KG | F8: =SUMIFS('Saída da Central'!$G:$G,'Saída da Central'!$C:$C,C8,'Saída da Central'!$F:$F,"Cozinha de Produção de Fracionados")-SUMIF('Produção de Fracionados'!$E:$E,C8,'Produção de Fracionados'!$G:$G) -> 5 | G8: =IF(F8<=(0),"⚠ ABAIXO DO MÍNIMO","✓ NORMAL") -> ✓ NORMAL
A9: Cozinha de Produção de Fracionados | B9: Bruto | C9: ='Cadastro Produtos Brutos'!A3 -> BR-002 | D9: ='Cadastro Produtos Brutos'!B3 -> Arroz Japonês | E9: ='Cadastro Produtos Brutos'!D3 -> KG | F9: =SUMIFS('Saída da Central'!$G:$G,'Saída da Central'!$C:$C,C9,'Saída da Central'!$F:$F,"Cozinha de Produção de Fracionados")-SUMIF('Produção de Fracionados'!$E:$E,C9,'Produção de Fracionados'!$G:$G) -> 2 | G9: =IF(F9<=(0),"⚠ ABAIXO DO MÍNIMO","✓ NORMAL") -> ✓ NORMAL
A10: Cozinha de Produção de Fracionados | B10: Bruto | C10: ='Cadastro Produtos Brutos'!A4 -> BR-003 | D10: ='Cadastro Produtos Brutos'!B4 -> Alface Americana | E10: ='Cadastro Produtos Brutos'!D4 -> UN | F10: =SUMIFS('Saída da Central'!$G:$G,'Saída da Central'!$C:$C,C10,'Saída da Central'!$F:$F,"Cozinha de Produção de Fracionados")-SUMIF('Produção de Fracionados'!$E:$E,C10,'Produção de Fracionados'!$G:$G) -> 0 | G10: =IF(F10<=(0),"⚠ ABAIXO DO MÍNIMO","✓ NORMAL") -> ⚠ ABAIXO DO MÍNIMO
A11: Cozinha de Produção de Fracionados | B11: Bruto | C11: ='Cadastro Produtos Brutos'!A5 -> BR-004 | D11: ='Cadastro Produtos Brutos'!B5 -> Filé de Frango | E11: ='Cadastro Produtos Brutos'!D5 -> KG | F11: =SUMIFS('Saída da Central'!$G:$G,'Saída da Central'!$C:$C,C11,'Saída da Central'!$F:$F,"Cozinha de Produção de Fracionados")-SUMIF('Produção de Fracionados'!$E:$E,C11,'Produção de Fracionados'!$G:$G) -> 0 | G11: =IF(F11<=(0),"⚠ ABAIXO DO MÍNIMO","✓ NORMAL") -> ⚠ ABAIXO DO MÍNIMO
A12: Cozinha de Produção de Fracionados | B12: Bruto | C12: ='Cadastro Produtos Brutos'!A6 -> BR-005 | D12: ='Cadastro Produtos Brutos'!B6 -> Tomate | E12: ='Cadastro Produtos Brutos'!D6 -> KG | F12: =SUMIFS('Saída da Central'!$G:$G,'Saída da Central'!$C:$C,C12,'Saída da Central'!$F:$F,"Cozinha de Produção de Fracionados")-SUMIF('Produção de Fracionados'!$E:$E,C12,'Produção de Fracionados'!$G:$G) -> 0 | G12: =IF(F12<=(0),"⚠ ABAIXO DO MÍNIMO","✓ NORMAL") -> ⚠ ABAIXO DO MÍNIMO
A13: Cozinha de Produção de Fracionados | B13: Bruto | C13: ='Cadastro Produtos Brutos'!A7 -> BR-006 | D13: ='Cadastro Produtos Brutos'!B7 -> Queijo Muçarela | E13: ='Cadastro Produtos Brutos'!D7 -> KG | F13: =SUMIFS('Saída da Central'!$G:$G,'Saída da Central'!$C:$C,C13,'Saída da Central'!$F:$F,"Cozinha de Produção de Fracionados")-SUMIF('Produção de Fracionados'!$E:$E,C13,'Produção de Fracionados'!$G:$G) -> 0 | G13: =IF(F13<=(0),"⚠ ABAIXO DO MÍNIMO","✓ NORMAL") -> ⚠ ABAIXO DO MÍNIMO
A14: Buffet Fran Casaria | B14: Bruto | C14: ='Cadastro Produtos Brutos'!A2 -> BR-001 | D14: ='Cadastro Produtos Brutos'!B2 -> Salmão Fresco | E14: ='Cadastro Produtos Brutos'!D2 -> KG | F14: =SUMIFS('Saída da Central'!$G:$G,'Saída da Central'!$C:$C,C14,'Saída da Central'!$F:$F,"Buffet Fran Casaria") -> 0 | G14: =IF(F14<=(0),"⚠ ABAIXO DO MÍNIMO","✓ NORMAL") -> ⚠ ABAIXO DO MÍNIMO
A15: Buffet Fran Casaria | B15: Bruto | C15: ='Cadastro Produtos Brutos'!A3 -> BR-002 | D15: ='Cadastro Produtos Brutos'!B3 -> Arroz Japonês | E15: ='Cadastro Produtos Brutos'!D3 -> KG | F15: =SUMIFS('Saída da Central'!$G:$G,'Saída da Central'!$C:$C,C15,'Saída da Central'!$F:$F,"Buffet Fran Casaria") -> 0 | G15: =IF(F15<=(0),"⚠ ABAIXO DO MÍNIMO","✓ NORMAL") -> ⚠ ABAIXO DO MÍNIMO
